Traceback (most recent call last):
  File "/opt/hostedtoolcache/Python/3.10.14/x64/lib/python3.10/site-packages/jupyter_cache/executors/utils.py", line 58, in single_nb_execution
    executenb(
  File "/opt/hostedtoolcache/Python/3.10.14/x64/lib/python3.10/site-packages/nbclient/client.py", line 1305, in execute
    return NotebookClient(nb=nb, resources=resources, km=km, **kwargs).execute()
  File "/opt/hostedtoolcache/Python/3.10.14/x64/lib/python3.10/site-packages/jupyter_core/utils/__init__.py", line 166, in wrapped
    return loop.run_until_complete(inner)
  File "/opt/hostedtoolcache/Python/3.10.14/x64/lib/python3.10/asyncio/base_events.py", line 649, in run_until_complete
    return future.result()
  File "/opt/hostedtoolcache/Python/3.10.14/x64/lib/python3.10/site-packages/nbclient/client.py", line 705, in async_execute
    await self.async_execute_cell(
  File "/opt/hostedtoolcache/Python/3.10.14/x64/lib/python3.10/site-packages/nbclient/client.py", line 1058, in async_execute_cell
    await self._check_raise_for_error(cell, cell_index, exec_reply)
  File "/opt/hostedtoolcache/Python/3.10.14/x64/lib/python3.10/site-packages/nbclient/client.py", line 914, in _check_raise_for_error
    raise CellExecutionError.from_cell_and_msg(cell, exec_reply_content)
nbclient.exceptions.CellExecutionError: An error occurred while executing the following cell:
------------------
# Get data from the data frame. 
# Use our helper function, convert_day_of_week_to_int, to convert the days of the week to ints
d = jnp.array(convert_day_of_week_to_int(data['Day-of-Week']).values)
i = jnp.array((data['Condition'] == 'Intoxication').astype(int).values)

N = len(d)
NUM_STEPS = 1000
result = cs349_mle(
    model_of_intoxication_given_day, 
    jrandom.PRNGKey(0),
    NUM_STEPS,
    N, 
    d=d, 
    i=i,
    learning_rate=0.01
)
------------------


[0;31m---------------------------------------------------------------------------[0m
[0;31mNameError[0m                                 Traceback (most recent call last)
Cell [0;32mIn[7], line 8[0m
[1;32m      6[0m N [38;5;241m=[39m [38;5;28mlen[39m(d)
[1;32m      7[0m NUM_STEPS [38;5;241m=[39m [38;5;241m1000[39m
[0;32m----> 8[0m result [38;5;241m=[39m [43mcs349_mle[49m[43m([49m
[1;32m      9[0m [43m    [49m[43mmodel_of_intoxication_given_day[49m[43m,[49m[43m [49m
[1;32m     10[0m [43m    [49m[43mjrandom[49m[38;5;241;43m.[39;49m[43mPRNGKey[49m[43m([49m[38;5;241;43m0[39;49m[43m)[49m[43m,[49m
[1;32m     11[0m [43m    [49m[43mNUM_STEPS[49m[43m,[49m
[1;32m     12[0m [43m    [49m[43mN[49m[43m,[49m[43m [49m
[1;32m     13[0m [43m    [49m[43md[49m[38;5;241;43m=[39;49m[43md[49m[43m,[49m[43m [49m
[1;32m     14[0m [43m    [49m[43mi[49m[38;5;241;43m=[39;49m[43mi[49m[43m,[49m
[1;32m     15[0m [43m    [49m[43mlearning_rate[49m[38;5;241;43m=[39;49m[38;5;241;43m0.01[39;49m
[1;32m     16[0m [43m)[49m

File [0;32m~/work/cs349-fall-2024/cs349-fall-2024/utils.py:70[0m, in [0;36mcs349_mle[0;34m(model, key, num_steps, learning_rate, *args, **kwargs)[0m
[1;32m     67[0m [38;5;28;01mdef[39;00m [38;5;21mguide[39m([38;5;241m*[39margs, [38;5;241m*[39m[38;5;241m*[39mkwargs):
[1;32m     68[0m     [38;5;28;01mpass[39;00m
[0;32m---> 70[0m optimizer [38;5;241m=[39m [43mnumpyro[49m[38;5;241m.[39moptim[38;5;241m.[39mAdam(step_size[38;5;241m=[39mlearning_rate)
[1;32m     71[0m svi [38;5;241m=[39m numpyro[38;5;241m.[39minfer[38;5;241m.[39mSVI(
[1;32m     72[0m     model, guide, optimizer, loss[38;5;241m=[39mnumpyro[38;5;241m.[39minfer[38;5;241m.[39mTrace_ELBO(),
[1;32m     73[0m )
[1;32m     75[0m svi_result [38;5;241m=[39m svi[38;5;241m.[39mrun(key, num_steps, [38;5;241m*[39margs, [38;5;241m*[39m[38;5;241m*[39mkwargs)

[0;31mNameError[0m: name 'numpyro' is not defined

